WARNING:root:Failed to find .card-title on repertuar/repertuar.html&rep_date=2025-02-15. Skipping this date.
WARNING:root:Failed to find .card-title on repertuar/repertuar.html&rep_date=2025-02-16. Skipping this date.
INFO:root:Data saved to movies_schedule_10.json
Traceback (most recent call last):
  File "D:\Poland_movies_result\Completed\123_Tecza.py", line 155, in <module>
    fetch_theater_and_movie_details()
  File "D:\Poland_movies_result\Completed\123_Tecza.py", line 25, in fetch_theater_and_movie_details
    page.goto("https://wckwalcz.pl/repertuar.html")
  File "C:\Users\Administrator\AppData\Local\Packages\PythonSoftwareFoundation.Python.3.11_qbz5n2kfra8p0\LocalCache\local-packages\Python311\site-packages\playwright\sync_api\_generated.py", line 9006, in goto
    self._sync(
  File "C:\Users\Administrator\AppData\Local\Packages\PythonSoftwareFoundation.Python.3.11_qbz5n2kfra8p0\LocalCache\local-packages\Python311\site-packages\playwright\_impl\_sync_base.py", line 115, in _sync
    return task.result()
           ^^^^^^^^^^^^^
  File "C:\Users\Administrator\AppData\Local\Packages\PythonSoftwareFoundation.Python.3.11_qbz5n2kfra8p0\LocalCache\local-packages\Python311\site-packages\playwright\_impl\_page.py", line 551, in goto
    return await self._main_frame.goto(**locals_to_params(locals()))
           ^^^^^^^^^^^^^^^^^^^^^^^^^^^^^^^^^^^^^^^^^^^^^^^^^^^^^^^^^
  File "C:\Users\Administrator\AppData\Local\Packages\PythonSoftwareFoundation.Python.3.11_qbz5n2kfra8p0\LocalCache\local-packages\Python311\site-packages\playwright\_impl\_frame.py", line 145, in goto
    await self._channel.send("goto", locals_to_params(locals()))
  File "C:\Users\Administrator\AppData\Local\Packages\PythonSoftwareFoundation.Python.3.11_qbz5n2kfra8p0\LocalCache\local-packages\Python311\site-packages\playwright\_impl\_connection.py", line 61, in send
    return await self._connection.wrap_api_call(
           ^^^^^^^^^^^^^^^^^^^^^^^^^^^^^^^^^^^^^
  File "C:\Users\Administrator\AppData\Local\Packages\PythonSoftwareFoundation.Python.3.11_qbz5n2kfra8p0\LocalCache\local-packages\Python311\site-packages\playwright\_impl\_connection.py", line 528, in wrap_api_call
    raise rewrite_error(error, f"{parsed_st['apiName']}: {error}") from None
playwright._impl._errors.Error: Page.goto: net::ERR_NAME_NOT_RESOLVED at https://wckwalcz.pl/repertuar.html
Call log:
  - navigating to "https://wckwalcz.pl/repertuar.html", waiting until "load"

Traceback (most recent call last):
  File "D:\Poland_movies_result\Completed\163_mok.olkusz.pl.py", line 156, in <module>
    fetch_theater_and_movie_details()
  File "D:\Poland_movies_result\Completed\163_mok.olkusz.pl.py", line 25, in fetch_theater_and_movie_details
    page.goto("https://mok.olkusz.pl/index.php/kino-zbyszek")
  File "C:\Users\Administrator\AppData\Local\Packages\PythonSoftwareFoundation.Python.3.11_qbz5n2kfra8p0\LocalCache\local-packages\Python311\site-packages\playwright\sync_api\_generated.py", line 9006, in goto
    self._sync(
  File "C:\Users\Administrator\AppData\Local\Packages\PythonSoftwareFoundation.Python.3.11_qbz5n2kfra8p0\LocalCache\local-packages\Python311\site-packages\playwright\_impl\_sync_base.py", line 115, in _sync
    return task.result()
           ^^^^^^^^^^^^^
  File "C:\Users\Administrator\AppData\Local\Packages\PythonSoftwareFoundation.Python.3.11_qbz5n2kfra8p0\LocalCache\local-packages\Python311\site-packages\playwright\_impl\_page.py", line 551, in goto
    return await self._main_frame.goto(**locals_to_params(locals()))
           ^^^^^^^^^^^^^^^^^^^^^^^^^^^^^^^^^^^^^^^^^^^^^^^^^^^^^^^^^
  File "C:\Users\Administrator\AppData\Local\Packages\PythonSoftwareFoundation.Python.3.11_qbz5n2kfra8p0\LocalCache\local-packages\Python311\site-packages\playwright\_impl\_frame.py", line 145, in goto
    await self._channel.send("goto", locals_to_params(locals()))
  File "C:\Users\Administrator\AppData\Local\Packages\PythonSoftwareFoundation.Python.3.11_qbz5n2kfra8p0\LocalCache\local-packages\Python311\site-packages\playwright\_impl\_connection.py", line 61, in send
    return await self._connection.wrap_api_call(
           ^^^^^^^^^^^^^^^^^^^^^^^^^^^^^^^^^^^^^
  File "C:\Users\Administrator\AppData\Local\Packages\PythonSoftwareFoundation.Python.3.11_qbz5n2kfra8p0\LocalCache\local-packages\Python311\site-packages\playwright\_impl\_connection.py", line 528, in wrap_api_call
    raise rewrite_error(error, f"{parsed_st['apiName']}: {error}") from None
playwright._impl._errors.Error: Page.goto: net::ERR_ABORTED; maybe frame was detached?
Call log:
  - navigating to "https://mok.olkusz.pl/index.php/kino-zbyszek", waiting until "load"

